Traceback (most recent call last):
  File "/Users/matteo/anaconda3/lib/python3.11/site-packages/jupyter_cache/executors/utils.py", line 58, in single_nb_execution
    executenb(
  File "/Users/matteo/anaconda3/lib/python3.11/site-packages/nbclient/client.py", line 1314, in execute
    return NotebookClient(nb=nb, resources=resources, km=km, **kwargs).execute()
           ^^^^^^^^^^^^^^^^^^^^^^^^^^^^^^^^^^^^^^^^^^^^^^^^^^^^^^^^^^^^^^^^^^^^^
  File "/Users/matteo/anaconda3/lib/python3.11/site-packages/jupyter_core/utils/__init__.py", line 165, in wrapped
    return loop.run_until_complete(inner)
           ^^^^^^^^^^^^^^^^^^^^^^^^^^^^^^
  File "/Users/matteo/anaconda3/lib/python3.11/asyncio/base_events.py", line 653, in run_until_complete
    return future.result()
           ^^^^^^^^^^^^^^^
  File "/Users/matteo/anaconda3/lib/python3.11/site-packages/nbclient/client.py", line 709, in async_execute
    await self.async_execute_cell(
  File "/Users/matteo/anaconda3/lib/python3.11/site-packages/nbclient/client.py", line 1062, in async_execute_cell
    await self._check_raise_for_error(cell, cell_index, exec_reply)
  File "/Users/matteo/anaconda3/lib/python3.11/site-packages/nbclient/client.py", line 918, in _check_raise_for_error
    raise CellExecutionError.from_cell_and_msg(cell, exec_reply_content)
nbclient.exceptions.CellExecutionError: An error occurred while executing the following cell:
------------------
import numpy as np
import pandas as pd
from matplotlib import cm
import matplotlib.pyplot as plt 
from mpl_toolkits.mplot3d import Axes3D 

# Parameters: 
# molar fraction in the feed
N = 100 #number of points
B0 = np.logspace(-3, 1.5, N)
q_M = np.logspace(1, 3, N)
C = 1 ; # arbitrary value of C'
B0, q_M = np.meshgrid(B0, q_M) 

q=q_M * B0 * C / (1+B0 * C)


#Plotting

figure=plt.figure(figsize=(10, 8))
axes = figure.gca(projection ='3d') 

plt.xticks(fontsize=14)
plt.yticks(fontsize=14)


surf=axes.plot_surface(q_M,B0,q,cmap=cm.coolwarm,
                       linewidth=0, antialiased=False,alpha=0.2)

contour=axes.contour(q_M,B0,q,np.linspace(100, 800, 10),cmap=cm.coolwarm)

plt.title('Adsorbed concentration vs $B_0$ / $q_M$', fontsize=18);
axes.set_xlabel('$q_M$', fontsize=14);
axes.set_ylabel('$B_0$',fontsize=14);
axes.set_zlabel('$q$',fontsize=14);
figure.colorbar(surf, shrink=0.5, aspect=5);
------------------


[0;31m---------------------------------------------------------------------------[0m
[0;31mTypeError[0m                                 Traceback (most recent call last)
Cell [0;32mIn[2], line 21[0m
[1;32m     18[0m [38;5;66;03m#Plotting[39;00m
[1;32m     20[0m figure[38;5;241m=[39mplt[38;5;241m.[39mfigure(figsize[38;5;241m=[39m([38;5;241m10[39m, [38;5;241m8[39m))
[0;32m---> 21[0m axes [38;5;241m=[39m [43mfigure[49m[38;5;241;43m.[39;49m[43mgca[49m[43m([49m[43mprojection[49m[43m [49m[38;5;241;43m=[39;49m[38;5;124;43m'[39;49m[38;5;124;43m3d[39;49m[38;5;124;43m'[39;49m[43m)[49m 
[1;32m     23[0m plt[38;5;241m.[39mxticks(fontsize[38;5;241m=[39m[38;5;241m14[39m)
[1;32m     24[0m plt[38;5;241m.[39myticks(fontsize[38;5;241m=[39m[38;5;241m14[39m)

[0;31mTypeError[0m: FigureBase.gca() got an unexpected keyword argument 'projection'

