Traceback (most recent call last):
  File "/Users/matteo/anaconda3/lib/python3.11/site-packages/jupyter_cache/executors/utils.py", line 58, in single_nb_execution
    executenb(
  File "/Users/matteo/anaconda3/lib/python3.11/site-packages/nbclient/client.py", line 1305, in execute
    return NotebookClient(nb=nb, resources=resources, km=km, **kwargs).execute()
           ^^^^^^^^^^^^^^^^^^^^^^^^^^^^^^^^^^^^^^^^^^^^^^^^^^^^^^^^^^^^^^^^^^^^^
  File "/Users/matteo/anaconda3/lib/python3.11/site-packages/jupyter_core/utils/__init__.py", line 165, in wrapped
    return loop.run_until_complete(inner)
           ^^^^^^^^^^^^^^^^^^^^^^^^^^^^^^
  File "/Users/matteo/anaconda3/lib/python3.11/asyncio/base_events.py", line 654, in run_until_complete
    return future.result()
           ^^^^^^^^^^^^^^^
  File "/Users/matteo/anaconda3/lib/python3.11/site-packages/nbclient/client.py", line 705, in async_execute
    await self.async_execute_cell(
  File "/Users/matteo/anaconda3/lib/python3.11/site-packages/nbclient/client.py", line 1058, in async_execute_cell
    await self._check_raise_for_error(cell, cell_index, exec_reply)
  File "/Users/matteo/anaconda3/lib/python3.11/site-packages/nbclient/client.py", line 914, in _check_raise_for_error
    raise CellExecutionError.from_cell_and_msg(cell, exec_reply_content)
nbclient.exceptions.CellExecutionError: An error occurred while executing the following cell:
------------------
import numpy as np
import pandas as pd
from matplotlib import cm
import matplotlib.pyplot as plt 
from mpl_toolkits.mplot3d import Axes3D 

# Parameters: 
# molar fraction in the feed
N = 100 #number of points
DeltaP = np.linspace(0, 1, N)
x_B = np.linspace(0, 0.8, N)
P_A= 1 
DeltaP, x_B = np.meshgrid(DeltaP, x_B) 

pi = - np.log(1-x_B)

#Flux Equation
J_A = P_A * (DeltaP - pi)


#Plotting

figure=plt.figure(figsize=(10, 8))
#axes = figure.add_axes([0.1,0.1,0.1,1.2,1.2,1.2])
axes = figure.gca(projection ='3d') 

plt.xticks(fontsize=14)
plt.yticks(fontsize=14)

surf=axes.plot_surface(x_B,DeltaP,J_A,cmap=cm.coolwarm,
                       linewidth=0, antialiased=False,alpha=0.5)

contour=axes.contour(x_B,DeltaP,J_A,[0])

plt.title('Osmotic Flux vs $\Delta{P}$ / $x_B$', fontsize=18);
axes.set_xlabel('$x_B$', fontsize=14);
axes.set_ylabel('$\Delta{P}$',fontsize=14);
figure.colorbar(surf, shrink=0.5, aspect=5);

------------------


[0;31m---------------------------------------------------------------------------[0m
[0;31mTypeError[0m                                 Traceback (most recent call last)
Cell [0;32mIn[2], line 25[0m
[1;32m     23[0m figure[38;5;241m=[39mplt[38;5;241m.[39mfigure(figsize[38;5;241m=[39m([38;5;241m10[39m, [38;5;241m8[39m))
[1;32m     24[0m [38;5;66;03m#axes = figure.add_axes([0.1,0.1,0.1,1.2,1.2,1.2])[39;00m
[0;32m---> 25[0m axes [38;5;241m=[39m figure[38;5;241m.[39mgca(projection [38;5;241m=[39m[38;5;124m'[39m[38;5;124m3d[39m[38;5;124m'[39m) 
[1;32m     27[0m plt[38;5;241m.[39mxticks(fontsize[38;5;241m=[39m[38;5;241m14[39m)
[1;32m     28[0m plt[38;5;241m.[39myticks(fontsize[38;5;241m=[39m[38;5;241m14[39m)

[0;31mTypeError[0m: FigureBase.gca() got an unexpected keyword argument 'projection'

